Workbook

Sheet CTRS_Summary
A1: Coastal tourism risk index (TSRI / CTRS) — result
A2: =CTRS_Calc!A2 -> X method in use: TOURISTS
A3: Higher TSRI = higher risk. Sorted by rank. Change options in CTRS_Control; tourist numbers go in CTRS_Inputs.
A5: Rank | B5: State | C5: Pantai share | D5: X | E5: Y | F5: Z | G5: TSRI | H5: TSRI (0–1) | I5: LCC note
A6: =IF(1<=SUM(CTRS_Calc!$Y$5:$Y$18),1,"") -> 1 | B6: =IF($A6="","",INDEX(CTRS_Calc!$A$5:$A$18,MATCH($A6,CTRS_Calc!$AE$5:$AE$18,0))) -> Pahang | C6: =IF($A6="","",INDEX(CTRS_Calc!$J$5:$J$18,MATCH($A6,CTRS_Calc!$AE$5:$AE$18,0))) -> 0.28196721 | D6: =IF($A6="","",INDEX(CTRS_Calc!$Z$5:$Z$18,MATCH($A6,CTRS_Calc!$AE$5:$AE$18,0))) -> 1 | E6: =IF($A6="","",INDEX(CTRS_Calc!$AA$5:$AA$18,MATCH($A6,CTRS_Calc!$AE$5:$AE$18,0))) -> 0.26648182 | F6: =IF($A6="","",INDEX(CTRS_Calc!$AB$5:$AB$18,MATCH($A6,CTRS_Calc!$AE$5:$AE$18,0))) -> 0.047504366 | G6: =IF($A6="","",INDEX(CTRS_Calc!$AC$5:$AC$18,MATCH($A6,CTRS_Calc!$AE$5:$AE$18,0))) -> 0.40632582 | H6: =IF($A6="","",INDEX(CTRS_Calc!$AD$5:$AD$18,MATCH($A6,CTRS_Calc!$AE$5:$AE$18,0))) -> 0.73965915 | I6: =IF($A6="","",IF(INDEX(CTRS_Calc!$AH$5:$AH$18,MATCH($A6,CTRS_Calc!$AE$5:$AE$18,0))=1,"no LCC data: substituted ("&CTRS_Control!$C$19&")",""))
A7: =IF(2<=SUM(CTRS_Calc!$Y$5:$Y$18),2,"") -> 2 | B7: =IF($A7="","",INDEX(CTRS_Calc!$A$5:$A$18,MATCH($A7,CTRS_Calc!$AE$5:$AE$18,0))) -> Kedah | C7: =IF($A7="","",INDEX(CTRS_Calc!$J$5:$J$18,MATCH($A7,CTRS_Calc!$AE$5:$AE$18,0))) -> 0.39664804 | D7: =IF($A7="","",INDEX(CTRS_Calc!$Z$5:$Z$18,MATCH($A7,CTRS_Calc!$AE$5:$AE$18,0))) -> 0.90735633 | E7: =IF($A7="","",INDEX(CTRS_Calc!$AA$5:$AA$18,MATCH($A7,CTRS_Calc!$AE$5:$AE$18,0))) -> 0.23459722 | F7: =IF($A7="","",INDEX(CTRS_Calc!$AB$5:$AB$18,MATCH($A7,CTRS_Calc!$AE$5:$AE$18,0))) -> 0.029259082 | G7: =IF($A7="","",INDEX(CTRS_Calc!$AC$5:$AC$18,MATCH($A7,CTRS_Calc!$AE$5:$AE$18,0))) -> 0.37089816 | H7: =IF($A7="","",INDEX(CTRS_Calc!$AD$5:$AD$18,MATCH($A7,CTRS_Calc!$AE$5:$AE$18,0))) -> 0.70423149 | I7: =IF($A7="","",IF(INDEX(CTRS_Calc!$AH$5:$AH$18,MATCH($A7,CTRS_Calc!$AE$5:$AE$18,0))=1,"no LCC data: substituted ("&CTRS_Control!$C$19&")",""))
A8: =IF(3<=SUM(CTRS_Calc!$Y$5:$Y$18),3,"") -> 3 | B8: =IF($A8="","",INDEX(CTRS_Calc!$A$5:$A$18,MATCH($A8,CTRS_Calc!$AE$5:$AE$18,0))) -> Terengganu | C8: =IF($A8="","",INDEX(CTRS_Calc!$J$5:$J$18,MATCH($A8,CTRS_Calc!$AE$5:$AE$18,0))) -> 0.54581673 | D8: =IF($A8="","",INDEX(CTRS_Calc!$Z$5:$Z$18,MATCH($A8,CTRS_Calc!$AE$5:$AE$18,0))) -> 0.91821756 | E8: =IF($A8="","",INDEX(CTRS_Calc!$AA$5:$AA$18,MATCH($A8,CTRS_Calc!$AE$5:$AE$18,0))) -> 0.28593424 | F8: =IF($A8="","",INDEX(CTRS_Calc!$AB$5:$AB$18,MATCH($A8,CTRS_Calc!$AE$5:$AE$18,0))) -> 0.25417178 | G8: =IF($A8="","",INDEX(CTRS_Calc!$AC$5:$AC$18,MATCH($A8,CTRS_Calc!$AE$5:$AE$18,0))) -> 0.31666001 | H8: =IF($A8="","",INDEX(CTRS_Calc!$AD$5:$AD$18,MATCH($A8,CTRS_Calc!$AE$5:$AE$18,0))) -> 0.64999334 | I8: =IF($A8="","",IF(INDEX(CTRS_Calc!$AH$5:$AH$18,MATCH($A8,CTRS_Calc!$AE$5:$AE$18,0))=1,"no LCC data: substituted ("&CTRS_Control!$C$19&")",""))
A9: =IF(4<=SUM(CTRS_Calc!$Y$5:$Y$18),4,"") -> 4 | B9: =IF($A9="","",INDEX(CTRS_Calc!$A$5:$A$18,MATCH($A9,CTRS_Calc!$AE$5:$AE$18,0))) -> Kelantan | C9: =IF($A9="","",INDEX(CTRS_Calc!$J$5:$J$18,MATCH($A9,CTRS_Calc!$AE$5:$AE$18,0))) -> 0.17582418 | D9: =IF($A9="","",INDEX(CTRS_Calc!$Z$5:$Z$18,MATCH($A9,CTRS_Calc!$AE$5:$AE$18,0))) -> 0.36761971 | E9: =IF($A9="","",INDEX(CTRS_Calc!$AA$5:$AA$18,MATCH($A9,CTRS_Calc!$AE$5:$AE$18,0))) -> 0.5275 | F9: =IF($A9="","",INDEX(CTRS_Calc!$AB$5:$AB$18,MATCH($A9,CTRS_Calc!$AE$5:$AE$18,0))) -> 0 | G9: =IF($A9="","",INDEX(CTRS_Calc!$AC$5:$AC$18,MATCH($A9,CTRS_Calc!$AE$5:$AE$18,0))) -> 0.29837324 | H9: =IF($A9="","",INDEX(CTRS_Calc!$AD$5:$AD$18,MATCH($A9,CTRS_Calc!$AE$5:$AE$18,0))) -> 0.63170657 | I9: =IF($A9="","",IF(INDEX(CTRS_Calc!$AH$5:$AH$18,MATCH($A9,CTRS_Calc!$AE$5:$AE$18,0))=1,"no LCC data: substituted ("&CTRS_Control!$C$19&")","")) -> no LCC data: substituted (ZERO)
A10: =IF(5<=SUM(CTRS_Calc!$Y$5:$Y$18),5,"") -> 5 | B10: =IF($A10="","",INDEX(CTRS_Calc!$A$5:$A$18,MATCH($A10,CTRS_Calc!$AE$5:$AE$18,0))) -> Perak | C10: =IF($A10="","",INDEX(CTRS_Calc!$J$5:$J$18,MATCH($A10,CTRS_Calc!$AE$5:$AE$18,0))) -> 0.14956012 | D10: =IF($A10="","",INDEX(CTRS_Calc!$Z$5:$Z$18,MATCH($A10,CTRS_Calc!$AE$5:$AE$18,0))) -> 0.50006102 | E10: =IF($A10="","",INDEX(CTRS_Calc!$AA$5:$AA$18,MATCH($A10,CTRS_Calc!$AE$5:$AE$18,0))) -> 0.370605 | F10: =IF($A10="","",INDEX(CTRS_Calc!$AB$5:$AB$18,MATCH($A10,CTRS_Calc!$AE$5:$AE$18,0))) -> 0 | G10: =IF($A10="","",INDEX(CTRS_Calc!$AC$5:$AC$18,MATCH($A10,CTRS_Calc!$AE$5:$AE$18,0))) -> 0.29022201 | H10: =IF($A10="","",INDEX(CTRS_Calc!$AD$5:$AD$18,MATCH($A10,CTRS_Calc!$AE$5:$AE$18,0))) -> 0.62355534 | I10: =IF($A10="","",IF(INDEX(CTRS_Calc!$AH$5:$AH$18,MATCH($A10,CTRS_Calc!$AE$5:$AE$18,0))=1,"no LCC data: substituted ("&CTRS_Control!$C$19&")",""))
A11: =IF(6<=SUM(CTRS_Calc!$Y$5:$Y$18),6,"") -> 6 | B11: =IF($A11="","",INDEX(CTRS_Calc!$A$5:$A$18,MATCH($A11,CTRS_Calc!$AE$5:$AE$18,0))) -> Selangor | C11: =IF($A11="","",INDEX(CTRS_Calc!$J$5:$J$18,MATCH($A11,CTRS_Calc!$AE$5:$AE$18,0))) -> 0.042654028 | D11: =IF($A11="","",INDEX(CTRS_Calc!$Z$5:$Z$18,MATCH($A11,CTRS_Calc!$AE$5:$AE$18,0))) -> 0.14510452 | E11: =IF($A11="","",INDEX(CTRS_Calc!$AA$5:$AA$18,MATCH($A11,CTRS_Calc!$AE$5:$AE$18,0))) -> 0.63583333 | F11: =IF($A11="","",INDEX(CTRS_Calc!$AB$5:$AB$18,MATCH($A11,CTRS_Calc!$AE$5:$AE$18,0))) -> 0 | G11: =IF($A11="","",INDEX(CTRS_Calc!$AC$5:$AC$18,MATCH($A11,CTRS_Calc!$AE$5:$AE$18,0))) -> 0.26031262 | H11: =IF($A11="","",INDEX(CTRS_Calc!$AD$5:$AD$18,MATCH($A11,CTRS_Calc!$AE$5:$AE$18,0))) -> 0.59364595 | I11: =IF($A11="","",IF(INDEX(CTRS_Calc!$AH$5:$AH$18,MATCH($A11,CTRS_Calc!$AE$5:$AE$18,0))=1,"no LCC data: substituted ("&CTRS_Control!$C$19&")","")) -> no LCC data: substituted (ZERO)
A12: =IF(7<=SUM(CTRS_Calc!$Y$5:$Y$18),7,"") -> 7 | B12: =IF($A12="","",INDEX(CTRS_Calc!$A$5:$A$18,MATCH($A12,CTRS_Calc!$AE$5:$AE$18,0))) -> Pulau Pinang | C12: =IF($A12="","",INDEX(CTRS_Calc!$J$5:$J$18,MATCH($A12,CTRS_Calc!$AE$5:$AE$18,0))) -> 0.083003953 | D12: =IF($A12="","",INDEX(CTRS_Calc!$Z$5:$Z$18,MATCH($A12,CTRS_Calc!$AE$5:$AE$18,0))) -> 0.1500269 | E12: =IF($A12="","",INDEX(CTRS_Calc!$AA$5:$AA$18,MATCH($A12,CTRS_Calc!$AE$5:$AE$18,0))) -> 0.59264706 | F12: =IF($A12="","",INDEX(CTRS_Calc!$AB$5:$AB$18,MATCH($A12,CTRS_Calc!$AE$5:$AE$18,0))) -> 0 | G12: =IF($A12="","",INDEX(CTRS_Calc!$AC$5:$AC$18,MATCH($A12,CTRS_Calc!$AE$5:$AE$18,0))) -> 0.24755799 | H12: =IF($A12="","",INDEX(CTRS_Calc!$AD$5:$AD$18,MATCH($A12,CTRS_Calc!$AE$5:$AE$18,0))) -> 0.58089132 | I12: =IF($A12="","",IF(INDEX(CTRS_Calc!$AH$5:$AH$18,MATCH($A12,CTRS_Calc!$AE$5:$AE$18,0))=1,"no LCC data: substituted ("&CTRS_Control!$C$19&")","")) -> no LCC data: substituted (ZERO)
A13: =IF(8<=SUM(CTRS_Calc!$Y$5:$Y$18),8,"") -> 8 | B13: =IF($A13="","",INDEX(CTRS_Calc!$A$5:$A$18,MATCH($A13,CTRS_Calc!$AE$5:$AE$18,0))) -> Johor | C13: =IF($A13="","",INDEX(CTRS_Calc!$J$5:$J$18,MATCH($A13,CTRS_Calc!$AE$5:$AE$18,0))) -> 0.13508065 | D13: =IF($A13="","",INDEX(CTRS_Calc!$Z$5:$Z$18,MATCH($A13,CTRS_Calc!$AE$5:$AE$18,0))) -> 0.42597663 | E13: =IF($A13="","",INDEX(CTRS_Calc!$AA$5:$AA$18,MATCH($A13,CTRS_Calc!$AE$5:$AE$18,0))) -> 0.31370226 | F13: =IF($A13="","",INDEX(CTRS_Calc!$AB$5:$AB$18,MATCH($A13,CTRS_Calc!$AE$5:$AE$18,0))) -> 0.17832116 | G13: =IF($A13="","",INDEX(CTRS_Calc!$AC$5:$AC$18,MATCH($A13,CTRS_Calc!$AE$5:$AE$18,0))) -> 0.18711924 | H13: =IF($A13="","",INDEX(CTRS_Calc!$AD$5:$AD$18,MATCH($A13,CTRS_Calc!$AE$5:$AE$18,0))) -> 0.52045258 | I13: =IF($A13="","",IF(INDEX(CTRS_Calc!$AH$5:$AH$18,MATCH($A13,CTRS_Calc!$AE$5:$AE$18,0))=1,"no LCC data: substituted ("&CTRS_Control!$C$19&")",""))
A14: =IF(9<=SUM(CTRS_Calc!$Y$5:$Y$18),9,"") -> 9 | B14: =IF($A14="","",INDEX(CTRS_Calc!$A$5:$A$18,MATCH($A14,CTRS_Calc!$AE$5:$AE$18,0))) -> W.P. Labuan | C14: =IF($A14="","",INDEX(CTRS_Calc!$J$5:$J$18,MATCH($A14,CTRS_Calc!$AE$5:$AE$18,0))) -> 0.046511628 | D14: =IF($A14="","",INDEX(CTRS_Calc!$Z$5:$Z$18,MATCH($A14,CTRS_Calc!$AE$5:$AE$18,0))) -> 0.0039840069 | E14: =IF($A14="","",INDEX(CTRS_Calc!$AA$5:$AA$18,MATCH($A14,CTRS_Calc!$AE$5:$AE$18,0))) -> 0.604 | F14: =IF($A14="","",INDEX(CTRS_Calc!$AB$5:$AB$18,MATCH($A14,CTRS_Calc!$AE$5:$AE$18,0))) -> 0.051691252 | G14: =IF($A14="","",INDEX(CTRS_Calc!$AC$5:$AC$18,MATCH($A14,CTRS_Calc!$AE$5:$AE$18,0))) -> 0.18543092 | H14: =IF($A14="","",INDEX(CTRS_Calc!$AD$5:$AD$18,MATCH($A14,CTRS_Calc!$AE$5:$AE$18,0))) -> 0.51876425 | I14: =IF($A14="","",IF(INDEX(CTRS_Calc!$AH$5:$AH$18,MATCH($A14,CTRS_Calc!$AE$5:$AE$18,0))=1,"no LCC data: substituted ("&CTRS_Control!$C$19&")","")) -> no LCC data: substituted (ZERO)
A15: =IF(10<=SUM(CTRS_Calc!$Y$5:$Y$18),10,"") -> 10 | B15: =IF($A15="","",INDEX(CTRS_Calc!$A$5:$A$18,MATCH($A15,CTRS_Calc!$AE$5:$AE$18,0))) -> Sabah | C15: =IF($A15="","",INDEX(CTRS_Calc!$J$5:$J$18,MATCH($A15,CTRS_Calc!$AE$5:$AE$18,0))) -> 0.059360731 | D15: =IF($A15="","",INDEX(CTRS_Calc!$Z$5:$Z$18,MATCH($A15,CTRS_Calc!$AE$5:$AE$18,0))) -> 0.14027092 | E15: =IF($A15="","",INDEX(CTRS_Calc!$AA$5:$AA$18,MATCH($A15,CTRS_Calc!$AE$5:$AE$18,0))) -> 0.41096312 | F15: =IF($A15="","",INDEX(CTRS_Calc!$AB$5:$AB$18,MATCH($A15,CTRS_Calc!$AE$5:$AE$18,0))) -> 0.11766119 | G15: =IF($A15="","",INDEX(CTRS_Calc!$AC$5:$AC$18,MATCH($A15,CTRS_Calc!$AE$5:$AE$18,0))) -> 0.14452428 | H15: =IF($A15="","",INDEX(CTRS_Calc!$AD$5:$AD$18,MATCH($A15,CTRS_Calc!$AE$5:$AE$18,0))) -> 0.47785762 | I15: =IF($A15="","",IF(INDEX(CTRS_Calc!$AH$5:$AH$18,MATCH($A15,CTRS_Calc!$AE$5:$AE$18,0))=1,"no LCC data: substituted ("&CTRS_Control!$C$19&")",""))
A16: =IF(11<=SUM(CTRS_Calc!$Y$5:$Y$18),11,"") -> 11 | B16: =IF($A16="","",INDEX(CTRS_Calc!$A$5:$A$18,MATCH($A16,CTRS_Calc!$AE$5:$AE$18,0))) -> Negeri Sembilan | C16: =IF($A16="","",INDEX(CTRS_Calc!$J$5:$J$18,MATCH($A16,CTRS_Calc!$AE$5:$AE$18,0))) -> 0.24375 | D16: =IF($A16="","",INDEX(CTRS_Calc!$Z$5:$Z$18,MATCH($A16,CTRS_Calc!$AE$5:$AE$18,0))) -> 0.51237228 | E16: =IF($A16="","",INDEX(CTRS_Calc!$AA$5:$AA$18,MATCH($A16,CTRS_Calc!$AE$5:$AE$18,0))) -> 0.45791429 | F16: =IF($A16="","",INDEX(CTRS_Calc!$AB$5:$AB$18,MATCH($A16,CTRS_Calc!$AE$5:$AE$18,0))) -> 0.54556922 | G16: =IF($A16="","",INDEX(CTRS_Calc!$AC$5:$AC$18,MATCH($A16,CTRS_Calc!$AE$5:$AE$18,0))) -> 0.14157245 | H16: =IF($A16="","",INDEX(CTRS_Calc!$AD$5:$AD$18,MATCH($A16,CTRS_Calc!$AE$5:$AE$18,0))) -> 0.47490578 | I16: =IF($A16="","",IF(INDEX(CTRS_Calc!$AH$5:$AH$18,MATCH($A16,CTRS_Calc!$AE$5:$AE$18,0))=1,"no LCC data: substituted ("&CTRS_Control!$C$19&")",""))
A17: =IF(12<=SUM(CTRS_Calc!$Y$5:$Y$18),12,"") -> 12 | B17: =IF($A17="","",INDEX(CTRS_Calc!$A$5:$A$18,MATCH($A17,CTRS_Calc!$AE$5:$AE$18,0))) -> Melaka | C17: =IF($A17="","",INDEX(CTRS_Calc!$J$5:$J$18,MATCH($A17,CTRS_Calc!$AE$5:$AE$18,0))) -> 0.12707182 | D17: =IF($A17="","",INDEX(CTRS_Calc!$Z$5:$Z$18,MATCH($A17,CTRS_Calc!$AE$5:$AE$18,0))) -> 0.29288129 | E17: =IF($A17="","",INDEX(CTRS_Calc!$AA$5:$AA$18,MATCH($A17,CTRS_Calc!$AE$5:$AE$18,0))) -> 0.44490556 | F17: =IF($A17="","",INDEX(CTRS_Calc!$AB$5:$AB$18,MATCH($A17,CTRS_Calc!$AE$5:$AE$18,0))) -> 0.66325507 | G17: =IF($A17="","",INDEX(CTRS_Calc!$AC$5:$AC$18,MATCH($A17,CTRS_Calc!$AE$5:$AE$18,0))) -> 0.024843926 | H17: =IF($A17="","",INDEX(CTRS_Calc!$AD$5:$AD$18,MATCH($A17,CTRS_Calc!$AE$5:$AE$18,0))) -> 0.35817726 | I17: =IF($A17="","",IF(INDEX(CTRS_Calc!$AH$5:$AH$18,MATCH($A17,CTRS_Calc!$AE$5:$AE$18,0))=1,"no LCC data: substituted ("&CTRS_Control!$C$19&")",""))
A18: =IF(13<=SUM(CTRS_Calc!$Y$5:$Y$18),13,"") -> 13 | B18: =IF($A18="","",INDEX(CTRS_Calc!$A$5:$A$18,MATCH($A18,CTRS_Calc!$AE$5:$AE$18,0))) -> Sarawak | C18: =IF($A18="","",INDEX(CTRS_Calc!$J$5:$J$18,MATCH($A18,CTRS_Calc!$AE$5:$AE$18,0))) -> 0.012820513 | D18: =IF($A18="","",INDEX(CTRS_Calc!$Z$5:$Z$18,MATCH($A18,CTRS_Calc!$AE$5:$AE$18,0))) -> 0.026055474 | E18: =IF($A18="","",INDEX(CTRS_Calc!$AA$5:$AA$18,MATCH($A18,CTRS_Calc!$AE$5:$AE$18,0))) -> 0.3744413 | F18: =IF($A18="","",INDEX(CTRS_Calc!$AB$5:$AB$18,MATCH($A18,CTRS_Calc!$AE$5:$AE$18,0))) -> 0.34069738 | G18: =IF($A18="","",INDEX(CTRS_Calc!$AC$5:$AC$18,MATCH($A18,CTRS_Calc!$AE$5:$AE$18,0))) -> 0.019933134 | H18: =IF($A18="","",INDEX(CTRS_Calc!$AD$5:$AD$18,MATCH($A18,CTRS_Calc!$AE$5:$AE$18,0))) -> 0.35326647 | I18: =IF($A18="","",IF(INDEX(CTRS_Calc!$AH$5:$AH$18,MATCH($A18,CTRS_Calc!$AE$5:$AE$18,0))=1,"no LCC data: substituted ("&CTRS_Control!$C$19&")",""))
A19: =IF(14<=SUM(CTRS_Calc!$Y$5:$Y$18),14,"") | B19: =IF($A19="","",INDEX(CTRS_Calc!$A$5:$A$18,MATCH($A19,CTRS_Calc!$AE$5:$AE$18,0))) | C19: =IF($A19="","",INDEX(CTRS_Calc!$J$5:$J$18,MATCH($A19,CTRS_Calc!$AE$5:$AE$18,0))) | D19: =IF($A19="","",INDEX(CTRS_Calc!$Z$5:$Z$18,MATCH($A19,CTRS_Calc!$AE$5:$AE$18,0))) | E19: =IF($A19="","",INDEX(CTRS_Calc!$AA$5:$AA$18,MATCH($A19,CTRS_Calc!$AE$5:$AE$18,0))) | F19: =IF($A19="","",INDEX(CTRS_Calc!$AB$5:$AB$18,MATCH($A19,CTRS_Calc!$AE$5:$AE$18,0))) | G19: =IF($A19="","",INDEX(CTRS_Calc!$AC$5:$AC$18,MATCH($A19,CTRS_Calc!$AE$5:$AE$18,0))) | H19: =IF($A19="","",INDEX(CTRS_Calc!$AD$5:$AD$18,MATCH($A19,CTRS_Calc!$AE$5:$AE$18,0))) | I19: =IF($A19="","",IF(INDEX(CTRS_Calc!$AH$5:$AH$18,MATCH($A19,CTRS_Calc!$AE$5:$AE$18,0))=1,"no LCC data: substituted ("&CTRS_Control!$C$19&")",""))
A21: ="States excluded (missing data): "&SUMPRODUCT(1-CTRS_Calc!$Y$5:$Y$18)&" — see CTRS_Calc col AF" -> States excluded (missing data): 1 — see CTRS_Calc col AF

Sheet CTRS_Control
A1: CTRS / TSRI — control panel
A2: Yellow cells = you can change. Everything else is formula. Pick from the dropdown.
B4: Switch | C4: Value | D4: Options / note
B5: HOTEL_BASIS | C5: HOTELS | D5: HOTELS | ROOMS — pantai share = beach hotels/total hotels (your spec) or beach rooms/total rooms
B6: TOTAL_BASIS | C6: REPORTED | D6: REPORTED | SUM_CATEGORIES — Johor total hotels (496) ≠ sum of its 4 categories (475); Terengganu total rooms (11,667) ≠ sum (11,677); see CTRS_Calc col AF
B7: X_METHOD | C7: AUTO | D7: AUTO | TOURISTS | SHARE_ONLY — TOURISTS = share × tourists (your plan). SHARE_ONLY = provisional, no tourist data needed. AUTO uses TOURISTS when every state that has hotel+MMWQI+LCC data also has a tourist count (now true)
B8: X_METHOD_IN_USE | C8: =IF(C7="AUTO",IF(AND(SUM(CTRS_Calc!$AG$5:$AG$18)>0,SUMPRODUCT(CTRS_Calc!$AG$5:$AG$18*CTRS_Calc!$X$5:$X$18)=SUM(CTRS_Calc!$AG$5:$AG$18)),"TOURISTS","SHARE_ONLY"),C7) -> TOURISTS | D8: Result of the switch above (formula)
B9: X_NORM | C9: MAX | D9: MAX (X / max X, same as original) | MINMAX
B10: MMWQI_YEAR | C10: 2025 | D10: 2021 | 2022 | 2023 | 2024 | 2025 — year of MMWQI used for the state mean (hotel data is 2025)
B11: LCC_WEIGHT | C11: SITES | D11: SITES (weight islands by no. of survey sites) | SIMPLE (plain mean of island LCC)
B12: w_X | C12: =1/3 -> 0.33333333 | D12: TSRI = w_X·X + w_Y·Y − w_Z·Z
B13: w_Y | C13: =1/3 -> 0.33333333
B14: w_Z | C14: =1/3 -> 0.33333333
B15: w_MMWQI | C15: =0.5 -> 0.5 | D15: Y = w_MMWQI·(1−MMWQI/100) + w_LCC·(1−LCC/100)
B16: w_LCC | C16: =0.5 -> 0.5
B17: weight check | C17: =IF(AND(ABS(C12+C13+C14-1)<0.000001,ABS(C15+C16-1)<0.000001),"OK","weights should sum to 1") -> OK
B18: TOURIST_YEAR | C18: 2025 | D18: 2021 | 2022 | 2023 | 2024 | 2025 — year of domestic tourists (DOSM DTS Table 10, all origins) used for X
B19: LCC_MISSING | C19: ZERO | D19: States with hotel+MMWQI data but no LCC survey sites: EXCLUDE (drop) | ZERO (LCC = 0%, Z = 0 → max coral stress, your idea) | NO_STRESS (LCC = 100%, Z = 0 → no coral stress) | MMWQI_ONLY (Y = MMWQI term only, Z = 0)
B30: Z_METHOD | C30: MPA_AREA | D30: MPA_AREA = protection-weighted protected marine area / total marine area (MPA sheet; weights in table below)
B31: Z_DENOM | C31: MYIMCA | D31: Total marine area used when Z_METHOD = MPA_AREA: MYIMCA (state marine area from MyIMCA sheet, shared sites split equally) | NATIONAL_SEA (Malaysia Territorial Sea from MPA sheet; Z scaled by max state) | MANUAL (type state marine areas in CTRS_Z column F)
B32: MPA_WEIGHTS | C32: LEVELS | D32: LEVELS = protection-weighted (stricter MPA counts more, see table) | BINARY = every MPA counts 1 (plain coverage)
B33: MPA TYPE → protection weight (protected area counted = size × weight). Edit yellow cells E:F.
B34: MPA sheet "TYPE" | C34: Weight used | D34: Note | E34: LEVELS weight | F34: BINARY weight
B35: MPA Most Restrictive | C35: =IF($C$32="LEVELS",E35,F35) -> 1 | D35: Anchor: 1.0 | E35: =1 -> 1 | F35: 1
B36: MPA Moderately Restrictive | C36: =IF($C$32="LEVELS",E36,F36) -> 0.83333333 | D36: Interpolated between most (1.0) and least (0.5) | E36: =5/6 -> 0.83333333 | F36: 1
B37: MPA Less Restrictive | C37: =IF($C$32="LEVELS",E37,F37) -> 0.66666667 | D37: Interpolated | E37: =2/3 -> 0.66666667 | F37: 1
B38: MPA Least Restrictive | C38: =IF($C$32="LEVELS",E38,F38) -> 0.5 | D38: Anchor: 0.5 | E38: =0.5 -> 0.5 | F38: 1
B39: Non-MPA Fisheries Management Area | C39: =IF($C$32="LEVELS",E39,F39) -> 0 | D39: Pulau Singa sea cucumber area (Kedah) | E39: 0 | F39: 0
B40: Non-MPA Jurisdictional Authority Area | C40: =IF($C$32="LEVELS",E40,F40) -> 0 | D40: National EEZ / Territorial Sea rows — not a state protected area | E40: 0 | F40: 0

Sheet CTRS_Inputs
A1: Domestic tourists by state (pulled from data)
A2: Unit: '000 tourists. Source: DOSM Domestic Tourism Survey, Table 10 (sheet total_number_of_tourist), origin = Malaysia (all origins). Year: CTRS_Control!C18.
A3: Yellow column = optional override in the same unit. Leave blank to use the data.
A5: State | B5: From data ('000) | C5: Override ('000) | D5: Used ('000)
A6: Johor | B6: =IF(COUNTIFS(total_number_of_tourist!$A$6:$A$300,"Malaysia",total_number_of_tourist!$B$6:$B$300,$A6)=0,"",SUMIFS(INDEX(total_number_of_tourist!$C$6:$Q$300,0,MATCH(CTRS_Control!$C$18&"",total_number_of_tourist!$C$5:$Q$5,0)),total_number_of_tourist!$A$6:$A$300,"Malaysia",total_number_of_tourist!$B$6:$B$300,$A6)) -> 9821.9 | D6: =IF(ISNUMBER(C6),C6,IF(ISNUMBER(B6),B6,"")) -> 9821.9
A7: Kedah | B7: =IF(COUNTIFS(total_number_of_tourist!$A$6:$A$300,"Malaysia",total_number_of_tourist!$B$6:$B$300,$A7)=0,"",SUMIFS(INDEX(total_number_of_tourist!$C$6:$Q$300,0,MATCH(CTRS_Control!$C$18&"",total_number_of_tourist!$C$5:$Q$5,0)),total_number_of_tourist!$A$6:$A$300,"Malaysia",total_number_of_tourist!$B$6:$B$300,$A7)) -> 7124.845 | D7: =IF(ISNUMBER(C7),C7,IF(ISNUMBER(B7),B7,"")) -> 7124.845
A8: Kelantan | B8: =IF(COUNTIFS(total_number_of_tourist!$A$6:$A$300,"Malaysia",total_number_of_tourist!$B$6:$B$300,$A8)=0,"",SUMIFS(INDEX(total_number_of_tourist!$C$6:$Q$300,0,MATCH(CTRS_Control!$C$18&"",total_number_of_tourist!$C$5:$Q$5,0)),total_number_of_tourist!$A$6:$A$300,"Malaysia",total_number_of_tourist!$B$6:$B$300,$A8)) -> 6512.13 | D8: =IF(ISNUMBER(C8),C8,IF(ISNUMBER(B8),B8,"")) -> 6512.13
A9: Melaka | B9: =IF(COUNTIFS(total_number_of_tourist!$A$6:$A$300,"Malaysia",total_number_of_tourist!$B$6:$B$300,$A9)=0,"",SUMIFS(INDEX(total_number_of_tourist!$C$6:$Q$300,0,MATCH(CTRS_Control!$C$18&"",total_number_of_tourist!$C$5:$Q$5,0)),total_number_of_tourist!$A$6:$A$300,"Malaysia",total_number_of_tourist!$B$6:$B$300,$A9)) -> 7178.6905 | D9: =IF(ISNUMBER(C9),C9,IF(ISNUMBER(B9),B9,"")) -> 7178.6905
A10: Negeri Sembilan | B10: =IF(COUNTIFS(total_number_of_tourist!$A$6:$A$300,"Malaysia",total_number_of_tourist!$B$6:$B$300,$A10)=0,"",SUMIFS(INDEX(total_number_of_tourist!$C$6:$Q$300,0,MATCH(CTRS_Control!$C$18&"",total_number_of_tourist!$C$5:$Q$5,0)),total_number_of_tourist!$A$6:$A$300,"Malaysia",total_number_of_tourist!$B$6:$B$300,$A10)) -> 6547.023 | D10: =IF(ISNUMBER(C10),C10,IF(ISNUMBER(B10),B10,"")) -> 6547.023
A11: Pahang | B11: =IF(COUNTIFS(total_number_of_tourist!$A$6:$A$300,"Malaysia",total_number_of_tourist!$B$6:$B$300,$A11)=0,"",SUMIFS(INDEX(total_number_of_tourist!$C$6:$Q$300,0,MATCH(CTRS_Control!$C$18&"",total_number_of_tourist!$C$5:$Q$5,0)),total_number_of_tourist!$A$6:$A$300,"Malaysia",total_number_of_tourist!$B$6:$B$300,$A11)) -> 11045.98 | D11: =IF(ISNUMBER(C11),C11,IF(ISNUMBER(B11),B11,"")) -> 11045.98
A12: Perak | B12: =IF(COUNTIFS(total_number_of_tourist!$A$6:$A$300,"Malaysia",total_number_of_tourist!$B$6:$B$300,$A12)=0,"",SUMIFS(INDEX(total_number_of_tourist!$C$6:$Q$300,0,MATCH(CTRS_Control!$C$18&"",total_number_of_tourist!$C$5:$Q$5,0)),total_number_of_tourist!$A$6:$A$300,"Malaysia",total_number_of_tourist!$B$6:$B$300,$A12)) -> 10413.82 | D12: =IF(ISNUMBER(C12),C12,IF(ISNUMBER(B12),B12,"")) -> 10413.82
A13: Perlis | B13: =IF(COUNTIFS(total_number_of_tourist!$A$6:$A$300,"Malaysia",total_number_of_tourist!$B$6:$B$300,$A13)=0,"",SUMIFS(INDEX(total_number_of_tourist!$C$6:$Q$300,0,MATCH(CTRS_Control!$C$18&"",total_number_of_tourist!$C$5:$Q$5,0)),total_number_of_tourist!$A$6:$A$300,"Malaysia",total_number_of_tourist!$B$6:$B$300,$A13)) -> 1474.936 | D13: =IF(ISNUMBER(C13),C13,IF(ISNUMBER(B13),B13,"")) -> 1474.936
A14: Pulau Pinang | B14: =IF(COUNTIFS(total_number_of_tourist!$A$6:$A$300,"Malaysia",total_number_of_tourist!$B$6:$B$300,$A14)=0,"",SUMIFS(INDEX(total_number_of_tourist!$C$6:$Q$300,0,MATCH(CTRS_Control!$C$18&"",total_number_of_tourist!$C$5:$Q$5,0)),total_number_of_tourist!$A$6:$A$300,"Malaysia",total_number_of_tourist!$B$6:$B$300,$A14)) -> 5629.544 | D14: =IF(ISNUMBER(C14),C14,IF(ISNUMBER(B14),B14,"")) -> 5629.544
A15: Sabah | B15: =IF(COUNTIFS(total_number_of_tourist!$A$6:$A$300,"Malaysia",total_number_of_tourist!$B$6:$B$300,$A15)=0,"",SUMIFS(INDEX(total_number_of_tourist!$C$6:$Q$300,0,MATCH(CTRS_Control!$C$18&"",total_number_of_tourist!$C$5:$Q$5,0)),total_number_of_tourist!$A$6:$A$300,"Malaysia",total_number_of_tourist!$B$6:$B$300,$A15)) -> 7359.889 | D15: =IF(ISNUMBER(C15),C15,IF(ISNUMBER(B15),B15,"")) -> 7359.889
A16: Sarawak | B16: =IF(COUNTIFS(total_number_of_tourist!$A$6:$A$300,"Malaysia",total_number_of_tourist!$B$6:$B$300,$A16)=0,"",SUMIFS(INDEX(total_number_of_tourist!$C$6:$Q$300,0,MATCH(CTRS_Control!$C$18&"",total_number_of_tourist!$C$5:$Q$5,0)),total_number_of_tourist!$A$6:$A$300,"Malaysia",total_number_of_tourist!$B$6:$B$300,$A16)) -> 6329.894 | D16: =IF(ISNUMBER(C16),C16,IF(ISNUMBER(B16),B16,"")) -> 6329.894
A17: Selangor | B17: =IF(COUNTIFS(total_number_of_tourist!$A$6:$A$300,"Malaysia",total_number_of_tourist!$B$6:$B$300,$A17)=0,"",SUMIFS(INDEX(total_number_of_tourist!$C$6:$Q$300,0,MATCH(CTRS_Control!$C$18&"",total_number_of_tourist!$C$5:$Q$5,0)),total_number_of_tourist!$A$6:$A$300,"Malaysia",total_number_of_tourist!$B$6:$B$300,$A17)) -> 10595.556 | D17: =IF(ISNUMBER(C17),C17,IF(ISNUMBER(B17),B17,"")) -> 10595.556
... A19: W.P. Labuan | B19: =IF(COUNTIFS(total_number_of_tourist!$A$6:$A$300,"Malaysia",total_number_of_tourist!$B$6:$B$300,$A19)=0,"",SUMIFS(INDEX(total_number_of_tourist!$C$6:$Q$300,0,MATCH(CTRS_Control!$C$18&"",total_number_of_tourist!$C$5:$Q$5,0)),total_number_of_tourist!$A$6:$A$300,"Malaysia",total_number_of_tourist!$B$6:$B$300,$A19)) -> 266.785 | D19: =IF(ISNUMBER(C19),C19,IF(ISNUMBER(B19),B19,"")) -> 266.785

Sheet CTRS_Calc
A1: Calculation sheet (formulas; blue cells in B:D are the state-name aliases used to match each source sheet)
A2: ="X method in use: "&CTRS_Control!C8&IF(CTRS_Control!C8="SHARE_ONLY"," (PROVISIONAL — add tourist counts in CTRS_Inputs)","") -> X method in use: TOURISTS
A4: State | B4: Name in hotel sheet | C4: Name in MMWQI sheet | D4: Name in LCC sheet | E4: Pantai hotels | F4: Total hotels (reported) | G4: Total hotels (sum of categories) | H4: Pantai rooms | I4: Total rooms | J4: Pantai share | K4: Domestic tourists ('000) | L4: Est. beach tourists ('000) = share × tourists | M4: X raw | N4: MMWQI stations (n) | O4: MMWQI mean | P4: MMWQI min | Q4: MMWQI max | R4: LCC survey sites | S4: LCC (%) | U4: Has hotel data | V4: Has MMWQI | W4: Has LCC | X4: Has tourists | Y4: Included in index | Z4: X | AA4: Y | AB4: Z | AC4: TSRI | AD4: TSRI (0–1) | AE4: Rank (1 = highest risk) | AF4: Data check | AG4: Core data complete | AH4: LCC substituted
A5: Johor | B5: Johor | C5: Johor | D5: Johor | E5: =SUMPRODUCT((hotel_location_2025!$A$2:$A$110=$B5)*(hotel_location_2025!$B$2:$B$110="Pantai/ Beach")*hotel_location_2025!$C$2:$C$110) -> 67 | F5: =SUMPRODUCT((hotel_location_2025!$A$2:$A$110=$B5)*(hotel_location_2025!$B$2:$B$110="Jumlah/ Total")*hotel_location_2025!$C$2:$C$110) -> 496 | G5: =SUMPRODUCT((hotel_location_2025!$A$2:$A$110=$B5)*(hotel_location_2025!$B$2:$B$110<>"Jumlah/ Total")*hotel_location_2025!$C$2:$C$110) -> 475 | H5: =SUMPRODUCT((hotel_location_2025!$A$2:$A$110=$B5)*(hotel_location_2025!$B$2:$B$110="Pantai/ Beach")*hotel_location_2025!$D$2:$D$110) -> 4476 | I5: =SUMPRODUCT((hotel_location_2025!$A$2:$A$110=$B5)*(hotel_location_2025!$B$2:$B$110="Jumlah/ Total")*hotel_location_2025!$D$2:$D$110) -> 33768 | J5: =IF(U5=0,"",IFERROR(IF(CTRS_Control!$C$5="ROOMS",H5/I5,E5/IF(CTRS_Control!$C$6="SUM_CATEGORIES",G5,F5)),"")) -> 0.13508065 | K5: =IF(ISNUMBER(INDEX(CTRS_Inputs!$D$6:$D$19,MATCH($A5,CTRS_Inputs!$A$6:$A$19,0))),INDEX(CTRS_Inputs!$D$6:$D$19,MATCH($A5,CTRS_Inputs!$A$6:$A$19,0)),"") -> 9821.9 | L5: =IF(AND(ISNUMBER(J5),ISNUMBER(K5)),J5*K5,"") -> 1326.7486 | M5: =IF(AG5=0,"",IF(CTRS_Control!$C$8="TOURISTS",IF(ISNUMBER(L5),L5,""),J5)) -> 1326.7486 | N5: =COUNTIF(MMWQI!$A$2:$A$400,$C5) -> 29 | O5: =IF(N5=0,"",AVERAGEIFS(INDEX(MMWQI!$E$2:$I$400,0,MATCH(VALUE(CTRS_Control!$C$10),MMWQI!$E$1:$I$1,0)),MMWQI!$A$2:$A$400,$C5)) -> 82.37931 | P5: =IF(N5=0,"",_xlfn.MINIFS(INDEX(MMWQI!$E$2:$I$400,0,MATCH(VALUE(CTRS_Control!$C$10),MMWQI!$E$1:$I$1,0)),MMWQI!$A$2:$A$400,$C5)) -> 52 | Q5: =IF(N5=0,"",_xlfn.MAXIFS(INDEX(MMWQI!$E$2:$I$400,0,MATCH(VALUE(CTRS_Control!$C$10),MMWQI!$E$1:$I$1,0)),MMWQI!$A$2:$A$400,$C5)) -> 96 | R5: =SUMIF(LCC!$B$2:$B$200,$D5,LCC!$D$2:$D$200) -> 84 | S5: =IF(R5>0,IF(CTRS_Control!$C$11="SITES",SUMPRODUCT((LCC!$B$2:$B$200=$D5)*LCC!$D$2:$D$200*LCC!$F$2:$F$200)/R5,AVERAGEIFS(LCC!$F$2:$F$200,LCC!$B$2:$B$200,$D5)),IF(AND(U5=1,V5=1),IF(CTRS_Control!$C$19="ZERO",0,IF(CTRS_Control!$C$19="NO_STRESS",100,"")),"")) -> 54.880238 | U5: =IF(COUNTIF(hotel_location_2025!$A$2:$A$110,$B5)>0,1,0) -> 1 | V5: =IF(N5>0,1,0) -> 1 | W5: =IF(R5>0,1,0) -> 1 | X5: =IF(ISNUMBER(K5),1,0) -> 1 | Y5: =IF(AND(AG5=1,ISNUMBER(M5)),1,0) -> 1 | Z5: =IF(Y5=1,IFERROR(IF(CTRS_Control!$C$9="MINMAX",(M5-MIN($M$5:$M$18))/(MAX($M$5:$M$18)-MIN($M$5:$M$18)),M5/MAX($M$5:$M$18)),0),"") -> 0.42597663 | AA5: =IF(Y5=1,IF(AND(R5=0,CTRS_Control!$C$19="MMWQI_ONLY"),1-O5/100,CTRS_Control!$C$15*(1-O5/100)+CTRS_Control!$C$16*(1-S5/100)),"") -> 0.31370226 | AB5: =IF(Y5=1,IF(ISNUMBER(CTRS_Z!$H5),CTRS_Z!$H5,0),"") -> 0.17832116 | AC5: =IF(Y5=1,CTRS_Control!$C$12*Z5+CTRS_Control!$C$13*AA5-CTRS_Control!$C$14*AB5,"") -> 0.18711924 | AD5: =IF(Y5=1,(AC5+CTRS_Control!$C$14)/(CTRS_Control!$C$12+CTRS_Control!$C$13+CTRS_Control!$C$14),"") -> 0.52045258 | AE5: =IF(Y5=1,RANK(AC5,$AC$5:$AC$18,0)+COUNTIF($AC$5:AC5,AC5)-1,"") -> 8 | AF5: =IF(U5=0,"No hotel data",IF(V5=0,"No MMWQI stations",IF(AND(W5=0,CTRS_Control!$C$19="EXCLUDE"),"No LCC sites",IF(AND(CTRS_Control!$C$8="TOURISTS",X5=0),"No tourist count",TRIM(IF(AH5=1,"No LCC data → substituted ("&CTRS_Control!$C$19&"). ","")&IF(F5<>G5,"Hotels: reported total "&F5&" ≠ sum of categories "&G5&". ","")&IF(I5<>SUMPRODUCT((hotel_location_2025!$A$2:$A$110=$B5)*(hotel_location_2025!$B$2:$B$110<>"Jumlah/ Total")*hotel_location_2025!$D$2:$D$110),"Rooms: reported total "&I5&" ≠ sum of categories "&SUMPRODUCT((hotel_location_2025!$A$2:$A$110=$B5)*(hotel_location_2025!$B$2:$B$110<>"Jumlah/ Total")*hotel_location_2025!$D$2:$D$110),"")))))) -> Hotels: reported total 496 ≠ sum of categories 475. | AG5: =U5*V5*IF(OR(W5=1,CTRS_Control!$C$19<>"EXCLUDE"),1,0) -> 1 | AH5: =IF(AND(Y5=1,R5=0),1,0) -> 0
A6: Kedah | B6: Kedah | C6: Kedah | D6: Kedah | E6: =SUMPRODUCT((hotel_location_2025!$A$2:$A$110=$B6)*(hotel_location_2025!$B$2:$B$110="Pantai/ Beach")*hotel_location_2025!$C$2:$C$110) -> 71 | F6: =SUMPRODUCT((hotel_location_2025!$A$2:$A$110=$B6)*(hotel_location_2025!$B$2:$B$110="Jumlah/ Total")*hotel_location_2025!$C$2:$C$110) -> 179 | G6: =SUMPRODUCT((hotel_location_2025!$A$2:$A$110=$B6)*(hotel_location_2025!$B$2:$B$110<>"Jumlah/ Total")*hotel_location_2025!$C$2:$C$110) -> 179 | H6: =SUMPRODUCT((hotel_location_2025!$A$2:$A$110=$B6)*(hotel_location_2025!$B$2:$B$110="Pantai/ Beach")*hotel_location_2025!$D$2:$D$110) -> 5256 | I6: =SUMPRODUCT((hotel_location_2025!$A$2:$A$110=$B6)*(hotel_location_2025!$B$2:$B$110="Jumlah/ Total")*hotel_location_2025!$D$2:$D$110) -> 13539 | J6: =IF(U6=0,"",IFERROR(IF(CTRS_Control!$C$5="ROOMS",H6/I6,E6/IF(CTRS_Control!$C$6="SUM_CATEGORIES",G6,F6)),"")) -> 0.39664804 | K6: =IF(ISNUMBER(INDEX(CTRS_Inputs!$D$6:$D$19,MATCH($A6,CTRS_Inputs!$A$6:$A$19,0))),INDEX(CTRS_Inputs!$D$6:$D$19,MATCH($A6,CTRS_Inputs!$A$6:$A$19,0)),"") -> 7124.845 | L6: =IF(AND(ISNUMBER(J6),ISNUMBER(K6)),J6*K6,"") -> 2826.0558 | M6: =IF(AG6=0,"",IF(CTRS_Control!$C$8="TOURISTS",IF(ISNUMBER(L6),L6,""),J6)) -> 2826.0558 | N6: =COUNTIF(MMWQI!$A$2:$A$400,$C6) -> 9 | O6: =IF(N6=0,"",AVERAGEIFS(INDEX(MMWQI!$E$2:$I$400,0,MATCH(VALUE(CTRS_Control!$C$10),MMWQI!$E$1:$I$1,0)),MMWQI!$A$2:$A$400,$C6)) -> 94.222222 | P6: =IF(N6=0,"",_xlfn.MINIFS(INDEX(MMWQI!$E$2:$I$400,0,MATCH(VALUE(CTRS_Control!$C$10),MMWQI!$E$1:$I$1,0)),MMWQI!$A$2:$A$400,$C6)) -> 88 | Q6: =IF(N6=0,"",_xlfn.MAXIFS(INDEX(MMWQI!$E$2:$I$400,0,MATCH(VALUE(CTRS_Control!$C$10),MMWQI!$E$1:$I$1,0)),MMWQI!$A$2:$A$400,$C6)) -> 96 | R6: =SUMIF(LCC!$B$2:$B$200,$D6,LCC!$D$2:$D$200) -> 6 | S6: =IF(R6>0,IF(CTRS_Control!$C$11="SITES",SUMPRODUCT((LCC!$B$2:$B$200=$D6)*LCC!$D$2:$D$200*LCC!$F$2:$F$200)/R6,AVERAGEIFS(LCC!$F$2:$F$200,LCC!$B$2:$B$200,$D6)),IF(AND(U6=1,V6=1),IF(CTRS_Control!$C$19="ZERO",0,IF(CTRS_Control!$C$19="NO_STRESS",100,"")),"")) -> 58.858333 | U6: =IF(COUNTIF(hotel_location_2025!$A$2:$A$110,$B6)>0,1,0) -> 1 | V6: =IF(N6>0,1,0) -> 1 | W6: =IF(R6>0,1,0) -> 1 | X6: =IF(ISNUMBER(K6),1,0) -> 1 | Y6: =IF(AND(AG6=1,ISNUMBER(M6)),1,0) -> 1 | Z6: =IF(Y6=1,IFERROR(IF(CTRS_Control!$C$9="MINMAX",(M6-MIN($M$5:$M$18))/(MAX($M$5:$M$18)-MIN($M$5:$M$18)),M6/MAX($M$5:$M$18)),0),"") -> 0.90735633 | AA6: =IF(Y6=1,IF(AND(R6=0,CTRS_Control!$C$19="MMWQI_ONLY"),1-O6/100,CTRS_Control!$C$15*(1-O6/100)+CTRS_Control!$C$16*(1-S6/100)),"") -> 0.23459722 | AB6: =IF(Y6=1,IF(ISNUMBER(CTRS_Z!$H6),CTRS_Z!$H6,0),"") -> 0.029259082 | AC6: =IF(Y6=1,CTRS_Control!$C$12*Z6+CTRS_Control!$C$13*AA6-CTRS_Control!$C$14*AB6,"") -> 0.37089816 | AD6: =IF(Y6=1,(AC6+CTRS_Control!$C$14)/(CTRS_Control!$C$12+CTRS_Control!$C$13+CTRS_Control!$C$14),"") -> 0.70423149 | AE6: =IF(Y6=1,RANK(AC6,$AC$5:$AC$18,0)+COUNTIF($AC$5:AC6,AC6)-1,"") -> 2 | AF6: =IF(U6=0,"No hotel data",IF(V6=0,"No MMWQI stations",IF(AND(W6=0,CTRS_Control!$C$19="EXCLUDE"),"No LCC sites",IF(AND(CTRS_Control!$C$8="TOURISTS",X6=0),"No tourist count",TRIM(IF(AH6=1,"No LCC data → substituted ("&CTRS_Control!$C$19&"). ","")&IF(F6<>G6,"Hotels: reported total "&F6&" ≠ sum of categories "&G6&". ","")&IF(I6<>SUMPRODUCT((hotel_location_2025!$A$2:$A$110=$B6)*(hotel_location_2025!$B$2:$B$110<>"Jumlah/ Total")*hotel_location_2025!$D$2:$D$110),"Rooms: reported total "&I6&" ≠ sum of categories "&SUMPRODUCT((hotel_location_2025!$A$2:$A$110=$B6)*(hotel_location_2025!$B$2:$B$110<>"Jumlah/ Total")*hotel_location_2025!$D$2:$D$110),"")))))) | AG6: =U6*V6*IF(OR(W6=1,CTRS_Control!$C$19<>"EXCLUDE"),1,0) -> 1 | AH6: =IF(AND(Y6=1,R6=0),1,0) -> 0
A7: Kelantan | B7: Kelantan | C7: Kelantan | D7: Kelantan | E7: =SUMPRODUCT((hotel_location_2025!$A$2:$A$110=$B7)*(hotel_location_2025!$B$2:$B$110="Pantai/ Beach")*hotel_location_2025!$C$2:$C$110) -> 16 | F7: =SUMPRODUCT((hotel_location_2025!$A$2:$A$110=$B7)*(hotel_location_2025!$B$2:$B$110="Jumlah/ Total")*hotel_location_2025!$C$2:$C$110) -> 91 | G7: =SUMPRODUCT((hotel_location_2025!$A$2:$A$110=$B7)*(hotel_location_2025!$B$2:$B$110<>"Jumlah/ Total")*hotel_location_2025!$C$2:$C$110) -> 91 | H7: =SUMPRODUCT((hotel_location_2025!$A$2:$A$110=$B7)*(hotel_location_2025!$B$2:$B$110="Pantai/ Beach")*hotel_location_2025!$D$2:$D$110) -> 679 | I7: =SUMPRODUCT((hotel_location_2025!$A$2:$A$110=$B7)*(hotel_location_2025!$B$2:$B$110="Jumlah/ Total")*hotel_location_2025!$D$2:$D$110) -> 4360 | J7: =IF(U7=0,"",IFERROR(IF(CTRS_Control!$C$5="ROOMS",H7/I7,E7/IF(CTRS_Control!$C$6="SUM_CATEGORIES",G7,F7)),"")) -> 0.17582418 | K7: =IF(ISNUMBER(INDEX(CTRS_Inputs!$D$6:$D$19,MATCH($A7,CTRS_Inputs!$A$6:$A$19,0))),INDEX(CTRS_Inputs!$D$6:$D$19,MATCH($A7,CTRS_Inputs!$A$6:$A$19,0)),"") -> 6512.13 | L7: =IF(AND(ISNUMBER(J7),ISNUMBER(K7)),J7*K7,"") -> 1144.9899 | M7: =IF(AG7=0,"",IF(CTRS_Control!$C$8="TOURISTS",IF(ISNUMBER(L7),L7,""),J7)) -> 1144.9899 | N7: =COUNTIF(MMWQI!$A$2:$A$400,$C7) -> 6 | O7: =IF(N7=0,"",AVERAGEIFS(INDEX(MMWQI!$E$2:$I$400,0,MATCH(VALUE(CTRS_Control!$C$10),MMWQI!$E$1:$I$1,0)),MMWQI!$A$2:$A$400,$C7)) -> 94.5 | P7: =IF(N7=0,"",_xlfn.MINIFS(INDEX(MMWQI!$E$2:$I$400,0,MATCH(VALUE(CTRS_Control!$C$10),MMWQI!$E$1:$I$1,0)),MMWQI!$A$2:$A$400,$C7)) -> 93 | Q7: =IF(N7=0,"",_xlfn.MAXIFS(INDEX(MMWQI!$E$2:$I$400,0,MATCH(VALUE(CTRS_Control!$C$10),MMWQI!$E$1:$I$1,0)),MMWQI!$A$2:$A$400,$C7)) -> 95 | R7: =SUMIF(LCC!$B$2:$B$200,$D7,LCC!$D$2:$D$200) -> 0 | S7: =IF(R7>0,IF(CTRS_Control!$C$11="SITES",SUMPRODUCT((LCC!$B$2:$B$200=$D7)*LCC!$D$2:$D$200*LCC!$F$2:$F$200)/R7,AVERAGEIFS(LCC!$F$2:$F$200,LCC!$B$2:$B$200,$D7)),IF(AND(U7=1,V7=1),IF(CTRS_Control!$C$19="ZERO",0,IF(CTRS_Control!$C$19="NO_STRESS",100,"")),"")) -> 0 | U7: =IF(COUNTIF(hotel_location_2025!$A$2:$A$110,$B7)>0,1,0) -> 1 | V7: =IF(N7>0,1,0) -> 1 | W7: =IF(R7>0,1,0) -> 0 | X7: =IF(ISNUMBER(K7),1,0) -> 1 | Y7: =IF(AND(AG7=1,ISNUMBER(M7)),1,0) -> 1 | Z7: =IF(Y7=1,IFERROR(IF(CTRS_Control!$C$9="MINMAX",(M7-MIN($M$5:$M$18))/(MAX($M$5:$M$18)-MIN($M$5:$M$18)),M7/MAX($M$5:$M$18)),0),"") -> 0.36761971 | AA7: =IF(Y7=1,IF(AND(R7=0,CTRS_Control!$C$19="MMWQI_ONLY"),1-O7/100,CTRS_Control!$C$15*(1-O7/100)+CTRS_Control!$C$16*(1-S7/100)),"") -> 0.5275 | AB7: =IF(Y7=1,IF(ISNUMBER(CTRS_Z!$H7),CTRS_Z!$H7,0),"") -> 0 | AC7: =IF(Y7=1,CTRS_Control!$C$12*Z7+CTRS_Control!$C$13*AA7-CTRS_Control!$C$14*AB7,"") -> 0.29837324 | AD7: =IF(Y7=1,(AC7+CTRS_Control!$C$14)/(CTRS_Control!$C$12+CTRS_Control!$C$13+CTRS_Control!$C$14),"") -> 0.63170657 | AE7: =IF(Y7=1,RANK(AC7,$AC$5:$AC$18,0)+COUNTIF($AC$5:AC7,AC7)-1,"") -> 4 | AF7: =IF(U7=0,"No hotel data",IF(V7=0,"No MMWQI stations",IF(AND(W7=0,CTRS_Control!$C$19="EXCLUDE"),"No LCC sites",IF(AND(CTRS_Control!$C$8="TOURISTS",X7=0),"No tourist count",TRIM(IF(AH7=1,"No LCC data → substituted ("&CTRS_Control!$C$19&"). ","")&IF(F7<>G7,"Hotels: reported total "&F7&" ≠ sum of categories "&G7&". ","")&IF(I7<>SUMPRODUCT((hotel_location_2025!$A$2:$A$110=$B7)*(hotel_location_2025!$B$2:$B$110<>"Jumlah/ Total")*hotel_location_2025!$D$2:$D$110),"Rooms: reported total "&I7&" ≠ sum of categories "&SUMPRODUCT((hotel_location_2025!$A$2:$A$110=$B7)*(hotel_location_2025!$B$2:$B$110<>"Jumlah/ Total")*hotel_location_2025!$D$2:$D$110),"")))))) -> No LCC data → substituted (ZERO). | AG7: =U7*V7*IF(OR(W7=1,CTRS_Control!$C$19<>"EXCLUDE"),1,0) -> 1 | AH7: =IF(AND(Y7=1,R7=0),1,0) -> 1
A8: Melaka | B8: Melaka | C8: Melaka | D8: Malacca | E8: =SUMPRODUCT((hotel_location_2025!$A$2:$A$110=$B8)*(hotel_location_2025!$B$2:$B$110="Pantai/ Beach")*hotel_location_2025!$C$2:$C$110) -> 23 | F8: =SUMPRODUCT((hotel_location_2025!$A$2:$A$110=$B8)*(hotel_location_2025!$B$2:$B$110="Jumlah/ Total")*hotel_location_2025!$C$2:$C$110) -> 181 | G8: =SUMPRODUCT((hotel_location_2025!$A$2:$A$110=$B8)*(hotel_location_2025!$B$2:$B$110<>"Jumlah/ Total")*hotel_location_2025!$C$2:$C$110) -> 181 | H8: =SUMPRODUCT((hotel_location_2025!$A$2:$A$110=$B8)*(hotel_location_2025!$B$2:$B$110="Pantai/ Beach")*hotel_location_2025!$D$2:$D$110) -> 3616 | I8: =SUMPRODUCT((hotel_location_2025!$A$2:$A$110=$B8)*(hotel_location_2025!$B$2:$B$110="Jumlah/ Total")*hotel_location_2025!$D$2:$D$110) -> 20550 | J8: =IF(U8=0,"",IFERROR(IF(CTRS_Control!$C$5="ROOMS",H8/I8,E8/IF(CTRS_Control!$C$6="SUM_CATEGORIES",G8,F8)),"")) -> 0.12707182 | K8: =IF(ISNUMBER(INDEX(CTRS_Inputs!$D$6:$D$19,MATCH($A8,CTRS_Inputs!$A$6:$A$19,0))),INDEX(CTRS_Inputs!$D$6:$D$19,MATCH($A8,CTRS_Inputs!$A$6:$A$19,0)),"") -> 7178.6905 | L8: =IF(AND(ISNUMBER(J8),ISNUMBER(K8)),J8*K8,"") -> 912.20929 | M8: =IF(AG8=0,"",IF(CTRS_Control!$C$8="TOURISTS",IF(ISNUMBER(L8),L8,""),J8)) -> 912.20929 | N8: =COUNTIF(MMWQI!$A$2:$A$400,$C8) -> 9 | O8: =IF(N8=0,"",AVERAGEIFS(INDEX(MMWQI!$E$2:$I$400,0,MATCH(VALUE(CTRS_Control!$C$10),MMWQI!$E$1:$I$1,0)),MMWQI!$A$2:$A$400,$C8)) -> 80.888889 | P8: =IF(N8=0,"",_xlfn.MINIFS(INDEX(MMWQI!$E$2:$I$400,0,MATCH(VALUE(CTRS_Control!$C$10),MMWQI!$E$1:$I$1,0)),MMWQI!$A$2:$A$400,$C8)) -> 58 | Q8: =IF(N8=0,"",_xlfn.MAXIFS(INDEX(MMWQI!$E$2:$I$400,0,MATCH(VALUE(CTRS_Control!$C$10),MMWQI!$E$1:$I$1,0)),MMWQI!$A$2:$A$400,$C8)) -> 91 | R8: =SUMIF(LCC!$B$2:$B$200,$D8,LCC!$D$2:$D$200) -> 5 | S8: =IF(R8>0,IF(CTRS_Control!$C$11="SITES",SUMPRODUCT((LCC!$B$2:$B$200=$D8)*LCC!$D$2:$D$200*LCC!$F$2:$F$200)/R8,AVERAGEIFS(LCC!$F$2:$F$200,LCC!$B$2:$B$200,$D8)),IF(AND(U8=1,V8=1),IF(CTRS_Control!$C$19="ZERO",0,IF(CTRS_Control!$C$19="NO_STRESS",100,"")),"")) -> 30.13 | U8: =IF(COUNTIF(hotel_location_2025!$A$2:$A$110,$B8)>0,1,0) -> 1 | V8: =IF(N8>0,1,0) -> 1 | W8: =IF(R8>0,1,0) -> 1 | X8: =IF(ISNUMBER(K8),1,0) -> 1 | Y8: =IF(AND(AG8=1,ISNUMBER(M8)),1,0) -> 1 | Z8: =IF(Y8=1,IFERROR(IF(CTRS_Control!$C$9="MINMAX",(M8-MIN($M$5:$M$18))/(MAX($M$5:$M$18)-MIN($M$5:$M$18)),M8/MAX($M$5:$M$18)),0),"") -> 0.29288129 | AA8: =IF(Y8=1,IF(AND(R8=0,CTRS_Control!$C$19="MMWQI_ONLY"),1-O8/100,CTRS_Control!$C$15*(1-O8/100)+CTRS_Control!$C$16*(1-S8/100)),"") -> 0.44490556 | AB8: =IF(Y8=1,IF(ISNUMBER(CTRS_Z!$H8),CTRS_Z!$H8,0),"") -> 0.66325507 | AC8: =IF(Y8=1,CTRS_Control!$C$12*Z8+CTRS_Control!$C$13*AA8-CTRS_Control!$C$14*AB8,"") -> 0.024843926 | AD8: =IF(Y8=1,(AC8+CTRS_Control!$C$14)/(CTRS_Control!$C$12+CTRS_Control!$C$13+CTRS_Control!$C$14),"") -> 0.35817726 | AE8: =IF(Y8=1,RANK(AC8,$AC$5:$AC$18,0)+COUNTIF($AC$5:AC8,AC8)-1,"") -> 12 | AF8: =IF(U8=0,"No hotel data",IF(V8=0,"No MMWQI stations",IF(AND(W8=0,CTRS_Control!$C$19="EXCLUDE"),"No LCC sites",IF(AND(CTRS_Control!$C$8="TOURISTS",X8=0),"No tourist count",TRIM(IF(AH8=1,"No LCC data → substituted ("&CTRS_Control!$C$19&"). ","")&IF(F8<>G8,"Hotels: reported total "&F8&" ≠ sum of categories "&G8&". ","")&IF(I8<>SUMPRODUCT((hotel_location_2025!$A$2:$A$110=$B8)*(hotel_location_2025!$B$2:$B$110<>"Jumlah/ Total")*hotel_location_2025!$D$2:$D$110),"Rooms: reported total "&I8&" ≠ sum of categories "&SUMPRODUCT((hotel_location_2025!$A$2:$A$110=$B8)*(hotel_location_2025!$B$2:$B$110<>"Jumlah/ Total")*hotel_location_2025!$D$2:$D$110),"")))))) | AG8: =U8*V8*IF(OR(W8=1,CTRS_Control!$C$19<>"EXCLUDE"),1,0) -> 1 | AH8: =IF(AND(Y8=1,R8=0),1,0) -> 0
A9: Negeri Sembilan | B9: Negeri Sembilan | C9: N. Sembilan | D9: Ng. Sembilan | E9: =SUMPRODUCT((hotel_location_2025!$A$2:$A$110=$B9)*(hotel_location_2025!$B$2:$B$110="Pantai/ Beach")*hotel_location_2025!$C$2:$C$110) -> 39 | F9: =SUMPRODUCT((hotel_location_2025!$A$2:$A$110=$B9)*(hotel_location_2025!$B$2:$B$110="Jumlah/ Total")*hotel_location_2025!$C$2:$C$110) -> 160 | G9: =SUMPRODUCT((hotel_location_2025!$A$2:$A$110=$B9)*(hotel_location_2025!$B$2:$B$110<>"Jumlah/ Total")*hotel_location_2025!$C$2:$C$110) -> 160 | H9: =SUMPRODUCT((hotel_location_2025!$A$2:$A$110=$B9)*(hotel_location_2025!$B$2:$B$110="Pantai/ Beach")*hotel_location_2025!$D$2:$D$110) -> 6057 | I9: =SUMPRODUCT((hotel_location_2025!$A$2:$A$110=$B9)*(hotel_location_2025!$B$2:$B$110="Jumlah/ Total")*hotel_location_2025!$D$2:$D$110) -> 13274 | J9: =IF(U9=0,"",IFERROR(IF(CTRS_Control!$C$5="ROOMS",H9/I9,E9/IF(CTRS_Control!$C$6="SUM_CATEGORIES",G9,F9)),"")) -> 0.24375 | K9: =IF(ISNUMBER(INDEX(CTRS_Inputs!$D$6:$D$19,MATCH($A9,CTRS_Inputs!$A$6:$A$19,0))),INDEX(CTRS_Inputs!$D$6:$D$19,MATCH($A9,CTRS_Inputs!$A$6:$A$19,0)),"") -> 6547.023 | L9: =IF(AND(ISNUMBER(J9),ISNUMBER(K9)),J9*K9,"") -> 1595.8369 | M9: =IF(AG9=0,"",IF(CTRS_Control!$C$8="TOURISTS",IF(ISNUMBER(L9),L9,""),J9)) -> 1595.8369 | N9: =COUNTIF(MMWQI!$A$2:$A$400,$C9) -> 14 | O9: =IF(N9=0,"",AVERAGEIFS(INDEX(MMWQI!$E$2:$I$400,0,MATCH(VALUE(CTRS_Control!$C$10),MMWQI!$E$1:$I$1,0)),MMWQI!$A$2:$A$400,$C9)) -> 91.857143 | P9: =IF(N9=0,"",_xlfn.MINIFS(INDEX(MMWQI!$E$2:$I$400,0,MATCH(VALUE(CTRS_Control!$C$10),MMWQI!$E$1:$I$1,0)),MMWQI!$A$2:$A$400,$C9)) -> 89 | Q9: =IF(N9=0,"",_xlfn.MAXIFS(INDEX(MMWQI!$E$2:$I$400,0,MATCH(VALUE(CTRS_Control!$C$10),MMWQI!$E$1:$I$1,0)),MMWQI!$A$2:$A$400,$C9)) -> 95 | R9: =SUMIF(LCC!$B$2:$B$200,$D9,LCC!$D$2:$D$200) -> 2 | S9: =IF(R9>0,IF(CTRS_Control!$C$11="SITES",SUMPRODUCT((LCC!$B$2:$B$200=$D9)*LCC!$D$2:$D$200*LCC!$F$2:$F$200)/R9,AVERAGEIFS(LCC!$F$2:$F$200,LCC!$B$2:$B$200,$D9)),IF(AND(U9=1,V9=1),IF(CTRS_Control!$C$19="ZERO",0,IF(CTRS_Control!$C$19="NO_STRESS",100,"")),"")) -> 16.56 | U9: =IF(COUNTIF(hotel_location_2025!$A$2:$A$110,$B9)>0,1,0) -> 1 | V9: =IF(N9>0,1,0) -> 1 | W9: =IF(R9>0,1,0) -> 1 | X9: =IF(ISNUMBER(K9),1,0) -> 1 | Y9: =IF(AND(AG9=1,ISNUMBER(M9)),1,0) -> 1 | Z9: =IF(Y9=1,IFERROR(IF(CTRS_Control!$C$9="MINMAX",(M9-MIN($M$5:$M$18))/(MAX($M$5:$M$18)-MIN($M$5:$M$18)),M9/MAX($M$5:$M$18)),0),"") -> 0.51237228 | AA9: =IF(Y9=1,IF(AND(R9=0,CTRS_Control!$C$19="MMWQI_ONLY"),1-O9/100,CTRS_Control!$C$15*(1-O9/100)+CTRS_Control!$C$16*(1-S9/100)),"") -> 0.45791429 | AB9: =IF(Y9=1,IF(ISNUMBER(CTRS_Z!$H9),CTRS_Z!$H9,0),"") -> 0.54556922 | AC9: =IF(Y9=1,CTRS_Control!$C$12*Z9+CTRS_Control!$C$13*AA9-CTRS_Control!$C$14*AB9,"") -> 0.14157245 | AD9: =IF(Y9=1,(AC9+CTRS_Control!$C$14)/(CTRS_Control!$C$12+CTRS_Control!$C$13+CTRS_Control!$C$14),"") -> 0.47490578 | AE9: =IF(Y9=1,RANK(AC9,$AC$5:$AC$18,0)+COUNTIF($AC$5:AC9,AC9)-1,"") -> 11 | AF9: =IF(U9=0,"No hotel data",IF(V9=0,"No MMWQI stations",IF(AND(W9=0,CTRS_Control!$C$19="EXCLUDE"),"No LCC sites",IF(AND(CTRS_Control!$C$8="TOURISTS",X9=0),"No tourist count",TRIM(IF(AH9=1,"No LCC data → substituted ("&CTRS_Control!$C$19&"). ","")&IF(F9<>G9,"Hotels: reported total "&F9&" ≠ sum of categories "&G9&". ","")&IF(I9<>SUMPRODUCT((hotel_location_2025!$A$2:$A$110=$B9)*(hotel_location_2025!$B$2:$B$110<>"Jumlah/ Total")*hotel_location_2025!$D$2:$D$110),"Rooms: reported total "&I9&" ≠ sum of categories "&SUMPRODUCT((hotel_location_2025!$A$2:$A$110=$B9)*(hotel_location_2025!$B$2:$B$110<>"Jumlah/ Total")*hotel_location_2025!$D$2:$D$110),"")))))) | AG9: =U9*V9*IF(OR(W9=1,CTRS_Control!$C$19<>"EXCLUDE"),1,0) -> 1 | AH9: =IF(AND(Y9=1,R9=0),1,0) -> 0
A10: Pahang | B10: Pahang | C10: Pahang | D10: Pahang | E10: =SUMPRODUCT((hotel_location_2025!$A$2:$A$110=$B10)*(hotel_location_2025!$B$2:$B$110="Pantai/ Beach")*hotel_location_2025!$C$2:$C$110) -> 86 | F10: =SUMPRODUCT((hotel_location_2025!$A$2:$A$110=$B10)*(hotel_location_2025!$B$2:$B$110="Jumlah/ Total")*hotel_location_2025!$C$2:$C$110) -> 305 | G10: =SUMPRODUCT((hotel_location_2025!$A$2:$A$110=$B10)*(hotel_location_2025!$B$2:$B$110<>"Jumlah/ Total")*hotel_location_2025!$C$2:$C$110) -> 305 | H10: =SUMPRODUCT((hotel_location_2025!$A$2:$A$110=$B10)*(hotel_location_2025!$B$2:$B$110="Pantai/ Beach")*hotel_location_2025!$D$2:$D$110) -> 4898 | I10: =SUMPRODUCT((hotel_location_2025!$A$2:$A$110=$B10)*(hotel_location_2025!$B$2:$B$110="Jumlah/ Total")*hotel_location_2025!$D$2:$D$110) -> 26037 | J10: =IF(U10=0,"",IFERROR(IF(CTRS_Control!$C$5="ROOMS",H10/I10,E10/IF(CTRS_Control!$C$6="SUM_CATEGORIES",G10,F10)),"")) -> 0.28196721 | K10: =IF(ISNUMBER(INDEX(CTRS_Inputs!$D$6:$D$19,MATCH($A10,CTRS_Inputs!$A$6:$A$19,0))),INDEX(CTRS_Inputs!$D$6:$D$19,MATCH($A10,CTRS_Inputs!$A$6:$A$19,0)),"") -> 11045.98 | L10: =IF(AND(ISNUMBER(J10),ISNUMBER(K10)),J10*K10,"") -> 3114.6042 | M10: =IF(AG10=0,"",IF(CTRS_Control!$C$8="TOURISTS",IF(ISNUMBER(L10),L10,""),J10)) -> 3114.6042 | N10: =COUNTIF(MMWQI!$A$2:$A$400,$C10) -> 22 | O10: =IF(N10=0,"",AVERAGEIFS(INDEX(MMWQI!$E$2:$I$400,0,MATCH(VALUE(CTRS_Control!$C$10),MMWQI!$E$1:$I$1,0)),MMWQI!$A$2:$A$400,$C10)) -> 93.363636 | P10: =IF(N10=0,"",_xlfn.MINIFS(INDEX(MMWQI!$E$2:$I$400,0,MATCH(VALUE(CTRS_Control!$C$10),MMWQI!$E$1:$I$1,0)),MMWQI!$A$2:$A$400,$C10)) -> 72 | Q10: =IF(N10=0,"",_xlfn.MAXIFS(INDEX(MMWQI!$E$2:$I$400,0,MATCH(VALUE(CTRS_Control!$C$10),MMWQI!$E$1:$I$1,0)),MMWQI!$A$2:$A$400,$C10)) -> 96 | R10: =SUMIF(LCC!$B$2:$B$200,$D10,LCC!$D$2:$D$200) -> 18 | S10: =IF(R10>0,IF(CTRS_Control!$C$11="SITES",SUMPRODUCT((LCC!$B$2:$B$200=$D10)*LCC!$D$2:$D$200*LCC!$F$2:$F$200)/R10,AVERAGEIFS(LCC!$F$2:$F$200,LCC!$B$2:$B$200,$D10)),IF(AND(U10=1,V10=1),IF(CTRS_Control!$C$19="ZERO",0,IF(CTRS_Control!$C$19="NO_STRESS",100,"")),"")) -> 53.34 | U10: =IF(COUNTIF(hotel_location_2025!$A$2:$A$110,$B10)>0,1,0) -> 1 | V10: =IF(N10>0,1,0) -> 1 | W10: =IF(R10>0,1,0) -> 1 | X10: =IF(ISNUMBER(K10),1,0) -> 1 | Y10: =IF(AND(AG10=1,ISNUMBER(M10)),1,0) -> 1 | Z10: =IF(Y10=1,IFERROR(IF(CTRS_Control!$C$9="MINMAX",(M10-MIN($M$5:$M$18))/(MAX($M$5:$M$18)-MIN($M$5:$M$18)),M10/MAX($M$5:$M$18)),0),"") -> 1 | AA10: =IF(Y10=1,IF(AND(R10=0,CTRS_Control!$C$19="MMWQI_ONLY"),1-O10/100,CTRS_Control!$C$15*(1-O10/100)+CTRS_Control!$C$16*(1-S10/100)),"") -> 0.26648182 | AB10: =IF(Y10=1,IF(ISNUMBER(CTRS_Z!$H10),CTRS_Z!$H10,0),"") -> 0.047504366 | AC10: =IF(Y10=1,CTRS_Control!$C$12*Z10+CTRS_Control!$C$13*AA10-CTRS_Control!$C$14*AB10,"") -> 0.40632582 | AD10: =IF(Y10=1,(AC10+CTRS_Control!$C$14)/(CTRS_Control!$C$12+CTRS_Control!$C$13+CTRS_Control!$C$14),"") -> 0.73965915 | AE10: =IF(Y10=1,RANK(AC10,$AC$5:$AC$18,0)+COUNTIF($AC$5:AC10,AC10)-1,"") -> 1 | AF10: =IF(U10=0,"No hotel data",IF(V10=0,"No MMWQI stations",IF(AND(W10=0,CTRS_Control!$C$19="EXCLUDE"),"No LCC sites",IF(AND(CTRS_Control!$C$8="TOURISTS",X10=0),"No tourist count",TRIM(IF(AH10=1,"No LCC data → substituted ("&CTRS_Control!$C$19&"). ","")&IF(F10<>G10,"Hotels: reported total "&F10&" ≠ sum of categories "&G10&". ","")&IF(I10<>SUMPRODUCT((hotel_location_2025!$A$2:$A$110=$B10)*(hotel_location_2025!$B$2:$B$110<>"Jumlah/ Total")*hotel_location_2025!$D$2:$D$110),"Rooms: reported total "&I10&" ≠ sum of categories "&SUMPRODUCT((hotel_location_2025!$A$2:$A$110=$B10)*(hotel_location_2025!$B$2:$B$110<>"Jumlah/ Total")*hotel_location_2025!$D$2:$D$110),"")))))) | AG10: =U10*V10*IF(OR(W10=1,CTRS_Control!$C$19<>"EXCLUDE"),1,0) -> 1 | AH10: =IF(AND(Y10=1,R10=0),1,0) -> 0
A11: Perak | B11: Perak | C11: Perak | D11: Perak | E11: =SUMPRODUCT((hotel_location_2025!$A$2:$A$110=$B11)*(hotel_location_2025!$B$2:$B$110="Pantai/ Beach")*hotel_location_2025!$C$2:$C$110) -> 51 | F11: =SUMPRODUCT((hotel_location_2025!$A$2:$A$110=$B11)*(hotel_location_2025!$B$2:$B$110="Jumlah/ Total")*hotel_location_2025!$C$2:$C$110) -> 341 | G11: =SUMPRODUCT((hotel_location_2025!$A$2:$A$110=$B11)*(hotel_location_2025!$B$2:$B$110<>"Jumlah/ Total")*hotel_location_2025!$C$2:$C$110) -> 341 | H11: =SUMPRODUCT((hotel_location_2025!$A$2:$A$110=$B11)*(hotel_location_2025!$B$2:$B$110="Pantai/ Beach")*hotel_location_2025!$D$2:$D$110) -> 3106 | I11: =SUMPRODUCT((hotel_location_2025!$A$2:$A$110=$B11)*(hotel_location_2025!$B$2:$B$110="Jumlah/ Total")*hotel_location_2025!$D$2:$D$110) -> 18181 | J11: =IF(U11=0,"",IFERROR(IF(CTRS_Control!$C$5="ROOMS",H11/I11,E11/IF(CTRS_Control!$C$6="SUM_CATEGORIES",G11,F11)),"")) -> 0.14956012 | K11: =IF(ISNUMBER(INDEX(CTRS_Inputs!$D$6:$D$19,MATCH($A11,CTRS_Inputs!$A$6:$A$19,0))),INDEX(CTRS_Inputs!$D$6:$D$19,MATCH($A11,CTRS_Inputs!$A$6:$A$19,0)),"") -> 10413.82 | L11: =IF(AND(ISNUMBER(J11),ISNUMBER(K11)),J11*K11,"") -> 1557.4921 | M11: =IF(AG11=0,"",IF(CTRS_Control!$C$8="TOURISTS",IF(ISNUMBER(L11),L11,""),J11)) -> 1557.4921 | N11: =COUNTIF(MMWQI!$A$2:$A$400,$C11) -> 8 | O11: =IF(N11=0,"",AVERAGEIFS(INDEX(MMWQI!$E$2:$I$400,0,MATCH(VALUE(CTRS_Control!$C$10),MMWQI!$E$1:$I$1,0)),MMWQI!$A$2:$A$400,$C11)) -> 93.375 | P11: =IF(N11=0,"",_xlfn.MINIFS(INDEX(MMWQI!$E$2:$I$400,0,MATCH(VALUE(CTRS_Control!$C$10),MMWQI!$E$1:$I$1,0)),MMWQI!$A$2:$A$400,$C11)) -> 91 | Q11: =IF(N11=0,"",_xlfn.MAXIFS(INDEX(MMWQI!$E$2:$I$400,0,MATCH(VALUE(CTRS_Control!$C$10),MMWQI!$E$1:$I$1,0)),MMWQI!$A$2:$A$400,$C11)) -> 96 | R11: =SUMIF(LCC!$B$2:$B$200,$D11,LCC!$D$2:$D$200) -> 10 | S11: =IF(R11>0,IF(CTRS_Control!$C$11="SITES",SUMPRODUCT((LCC!$B$2:$B$200=$D11)*LCC!$D$2:$D$200*LCC!$F$2:$F$200)/R11,AVERAGEIFS(LCC!$F$2:$F$200,LCC!$B$2:$B$200,$D11)),IF(AND(U11=1,V11=1),IF(CTRS_Control!$C$19="ZERO",0,IF(CTRS_Control!$C$19="NO_STRESS",100,"")),"")) -> 32.504 | U11: =IF(COUNTIF(hotel_location_2025!$A$2:$A$110,$B11)>0,1,0) -> 1 | V11: =IF(N11>0,1,0) -> 1 | W11: =IF(R11>0,1,0) -> 1 | X11: =IF(ISNUMBER(K11),1,0) -> 1 | Y11: =IF(AND(AG11=1,ISNUMBER(M11)),1,0) -> 1 | Z11: =IF(Y11=1,IFERROR(IF(CTRS_Control!$C$9="MINMAX",(M11-MIN($M$5:$M$18))/(MAX($M$5:$M$18)-MIN($M$5:$M$18)),M11/MAX($M$5:$M$18)),0),"") -> 0.50006102 | AA11: =IF(Y11=1,IF(AND(R11=0,CTRS_Control!$C$19="MMWQI_ONLY"),1-O11/100,CTRS_Control!$C$15*(1-O11/100)+CTRS_Control!$C$16*(1-S11/100)),"") -> 0.370605 | AB11: =IF(Y11=1,IF(ISNUMBER(CTRS_Z!$H11),CTRS_Z!$H11,0),"") -> 0 | AC11: =IF(Y11=1,CTRS_Control!$C$12*Z11+CTRS_Control!$C$13*AA11-CTRS_Control!$C$14*AB11,"") -> 0.29022201 | AD11: =IF(Y11=1,(AC11+CTRS_Control!$C$14)/(CTRS_Control!$C$12+CTRS_Control!$C$13+CTRS_Control!$C$14),"") -> 0.62355534 | AE11: =IF(Y11=1,RANK(AC11,$AC$5:$AC$18,0)+COUNTIF($AC$5:AC11,AC11)-1,"") -> 5 | AF11: =IF(U11=0,"No hotel data",IF(V11=0,"No MMWQI stations",IF(AND(W11=0,CTRS_Control!$C$19="EXCLUDE"),"No LCC sites",IF(AND(CTRS_Control!$C$8="TOURISTS",X11=0),"No tourist count",TRIM(IF(AH11=1,"No LCC data → substituted ("&CTRS_Control!$C$19&"). ","")&IF(F11<>G11,"Hotels: reported total "&F11&" ≠ sum of categories "&G11&". ","")&IF(I11<>SUMPRODUCT((hotel_location_2025!$A$2:$A$110=$B11)*(hotel_location_2025!$B$2:$B$110<>"Jumlah/ Total")*hotel_location_2025!$D$2:$D$110),"Rooms: reported total "&I11&" ≠ sum of categories "&SUMPRODUCT((hotel_location_2025!$A$2:$A$110=$B11)*(hotel_location_2025!$B$2:$B$110<>"Jumlah/ Total")*hotel_location_2025!$D$2:$D$110),"")))))) | AG11: =U11*V11*IF(OR(W11=1,CTRS_Control!$C$19<>"EXCLUDE"),1,0) -> 1 | AH11: =IF(AND(Y11=1,R11=0),1,0) -> 0
A12: Perlis | B12: Perlis | C12: Perlis | D12: Perlis | E12: =SUMPRODUCT((hotel_location_2025!$A$2:$A$110=$B12)*(hotel_location_2025!$B$2:$B$110="Pantai/ Beach")*hotel_location_2025!$C$2:$C$110) -> 2 | F12: =SUMPRODUCT((hotel_location_2025!$A$2:$A$110=$B12)*(hotel_location_2025!$B$2:$B$110="Jumlah/ Total")*hotel_location_2025!$C$2:$C$110) -> 33 | G12: =SUMPRODUCT((hotel_location_2025!$A$2:$A$110=$B12)*(hotel_location_2025!$B$2:$B$110<>"Jumlah/ Total")*hotel_location_2025!$C$2:$C$110) -> 33 | H12: =SUMPRODUCT((hotel_location_2025!$A$2:$A$110=$B12)*(hotel_location_2025!$B$2:$B$110="Pantai/ Beach")*hotel_location_2025!$D$2:$D$110) -> 150 | I12: =SUMPRODUCT((hotel_location_2025!$A$2:$A$110=$B12)*(hotel_location_2025!$B$2:$B$110="Jumlah/ Total")*hotel_location_2025!$D$2:$D$110) -> 1321 | J12: =IF(U12=0,"",IFERROR(IF(CTRS_Control!$C$5="ROOMS",H12/I12,E12/IF(CTRS_Control!$C$6="SUM_CATEGORIES",G12,F12)),"")) -> 0.060606061 | K12: =IF(ISNUMBER(INDEX(CTRS_Inputs!$D$6:$D$19,MATCH($A12,CTRS_Inputs!$A$6:$A$19,0))),INDEX(CTRS_Inputs!$D$6:$D$19,MATCH($A12,CTRS_Inputs!$A$6:$A$19,0)),"") -> 1474.936 | L12: =IF(AND(ISNUMBER(J12),ISNUMBER(K12)),J12*K12,"") -> 89.390061 | M12: =IF(AG12=0,"",IF(CTRS_Control!$C$8="TOURISTS",IF(ISNUMBER(L12),L12,""),J12)) | N12: =COUNTIF(MMWQI!$A$2:$A$400,$C12) -> 0 | O12: =IF(N12=0,"",AVERAGEIFS(INDEX(MMWQI!$E$2:$I$400,0,MATCH(VALUE(CTRS_Control!$C$10),MMWQI!$E$1:$I$1,0)),MMWQI!$A$2:$A$400,$C12)) | P12: =IF(N12=0,"",_xlfn.MINIFS(INDEX(MMWQI!$E$2:$I$400,0,MATCH(VALUE(CTRS_Control!$C$10),MMWQI!$E$1:$I$1,0)),MMWQI!$A$2:$A$400,$C12)) | Q12: =IF(N12=0,"",_xlfn.MAXIFS(INDEX(MMWQI!$E$2:$I$400,0,MATCH(VALUE(CTRS_Control!$C$10),MMWQI!$E$1:$I$1,0)),MMWQI!$A$2:$A$400,$C12)) | R12: =SUMIF(LCC!$B$2:$B$200,$D12,LCC!$D$2:$D$200) -> 0 | S12: =IF(R12>0,IF(CTRS_Control!$C$11="SITES",SUMPRODUCT((LCC!$B$2:$B$200=$D12)*LCC!$D$2:$D$200*LCC!$F$2:$F$200)/R12,AVERAGEIFS(LCC!$F$2:$F$200,LCC!$B$2:$B$200,$D12)),IF(AND(U12=1,V12=1),IF(CTRS_Control!$C$19="ZERO",0,IF(CTRS_Control!$C$19="NO_STRESS",100,"")),"")) | U12: =IF(COUNTIF(hotel_location_2025!$A$2:$A$110,$B12)>0,1,0) -> 1 | V12: =IF(N12>0,1,0) -> 0 | W12: =IF(R12>0,1,0) -> 0 | X12: =IF(ISNUMBER(K12),1,0) -> 1 | Y12: =IF(AND(AG12=1,ISNUMBER(M12)),1,0) -> 0 | Z12: =IF(Y12=1,IFERROR(IF(CTRS_Control!$C$9="MINMAX",(M12-MIN($M$5:$M$18))/(MAX($M$5:$M$18)-MIN($M$5:$M$18)),M12/MAX($M$5:$M$18)),0),"") | AA12: =IF(Y12=1,IF(AND(R12=0,CTRS_Control!$C$19="MMWQI_ONLY"),1-O12/100,CTRS_Control!$C$15*(1-O12/100)+CTRS_Control!$C$16*(1-S12/100)),"") | AB12: =IF(Y12=1,IF(ISNUMBER(CTRS_Z!$H12),CTRS_Z!$H12,0),"") | AC12: =IF(Y12=1,CTRS_Control!$C$12*Z12+CTRS_Control!$C$13*AA12-CTRS_Control!$C$14*AB12,"") | AD12: =IF(Y12=1,(AC12+CTRS_Control!$C$14)/(CTRS_Control!$C$12+CTRS_Control!$C$13+CTRS_Control!$C$14),"") | AE12: =IF(Y12=1,RANK(AC12,$AC$5:$AC$18,0)+COUNTIF($AC$5:AC12,AC12)-1,"") | AF12: =IF(U12=0,"No hotel data",IF(V12=0,"No MMWQI stations",IF(AND(W12=0,CTRS_Control!$C$19="EXCLUDE"),"No LCC sites",IF(AND(CTRS_Control!$C$8="TOURISTS",X12=0),"No tourist count",TRIM(IF(AH12=1,"No LCC data → substituted ("&CTRS_Control!$C$19&"). ","")&IF(F12<>G12,"Hotels: reported total "&F12&" ≠ sum of categories "&G12&". ","")&IF(I12<>SUMPRODUCT((hotel_location_2025!$A$2:$A$110=$B12)*(hotel_location_2025!$B$2:$B$110<>"Jumlah/ Total")*hotel_location_2025!$D$2:$D$110),"Rooms: reported total "&I12&" ≠ sum of categories "&SUMPRODUCT((hotel_location_2025!$A$2:$A$110=$B12)*(hotel_location_2025!$B$2:$B$110<>"Jumlah/ Total")*hotel_location_2025!$D$2:$D$110),"")))))) -> No MMWQI stations | AG12: =U12*V12*IF(OR(W12=1,CTRS_Control!$C$19<>"EXCLUDE"),1,0) -> 0 | AH12: =IF(AND(Y12=1,R12=0),1,0) -> 0
A13: Pulau Pinang | B13: Pulau Pinang | C13: P. Pinang | D13: Pulau Pinang | E13: =SUMPRODUCT((hotel_location_2025!$A$2:$A$110=$B13)*(hotel_location_2025!$B$2:$B$110="Pantai/ Beach")*hotel_location_2025!$C$2:$C$110) -> 21 | F13: =SUMPRODUCT((hotel_location_2025!$A$2:$A$110=$B13)*(hotel_location_2025!$B$2:$B$110="Jumlah/ Total")*hotel_location_2025!$C$2:$C$110) -> 253 | G13: =SUMPRODUCT((hotel_location_2025!$A$2:$A$110=$B13)*(hotel_location_2025!$B$2:$B$110<>"Jumlah/ Total")*hotel_location_2025!$C$2:$C$110) -> 253 | H13: =SUMPRODUCT((hotel_location_2025!$A$2:$A$110=$B13)*(hotel_location_2025!$B$2:$B$110="Pantai/ Beach")*hotel_location_2025!$D$2:$D$110) -> 4424 | I13: =SUMPRODUCT((hotel_location_2025!$A$2:$A$110=$B13)*(hotel_location_2025!$B$2:$B$110="Jumlah/ Total")*hotel_location_2025!$D$2:$D$110) -> 25603 | J13: =IF(U13=0,"",IFERROR(IF(CTRS_Control!$C$5="ROOMS",H13/I13,E13/IF(CTRS_Control!$C$6="SUM_CATEGORIES",G13,F13)),"")) -> 0.083003953 | K13: =IF(ISNUMBER(INDEX(CTRS_Inputs!$D$6:$D$19,MATCH($A13,CTRS_Inputs!$A$6:$A$19,0))),INDEX(CTRS_Inputs!$D$6:$D$19,MATCH($A13,CTRS_Inputs!$A$6:$A$19,0)),"") -> 5629.544 | L13: =IF(AND(ISNUMBER(J13),ISNUMBER(K13)),J13*K13,"") -> 467.2744 | M13: =IF(AG13=0,"",IF(CTRS_Control!$C$8="TOURISTS",IF(ISNUMBER(L13),L13,""),J13)) -> 467.2744 | N13: =COUNTIF(MMWQI!$A$2:$A$400,$C13) -> 17 | O13: =IF(N13=0,"",AVERAGEIFS(INDEX(MMWQI!$E$2:$I$400,0,MATCH(VALUE(CTRS_Control!$C$10),MMWQI!$E$1:$I$1,0)),MMWQI!$A$2:$A$400,$C13)) -> 81.470588 | P13: =IF(N13=0,"",_xlfn.MINIFS(INDEX(MMWQI!$E$2:$I$400,0,MATCH(VALUE(CTRS_Control!$C$10),MMWQI!$E$1:$I$1,0)),MMWQI!$A$2:$A$400,$C13)) -> 57 | Q13: =IF(N13=0,"",_xlfn.MAXIFS(INDEX(MMWQI!$E$2:$I$400,0,MATCH(VALUE(CTRS_Control!$C$10),MMWQI!$E$1:$I$1,0)),MMWQI!$A$2:$A$400,$C13)) -> 94 | R13: =SUMIF(LCC!$B$2:$B$200,$D13,LCC!$D$2:$D$200) -> 0 | S13: =IF(R13>0,IF(CTRS_Control!$C$11="SITES",SUMPRODUCT((LCC!$B$2:$B$200=$D13)*LCC!$D$2:$D$200*LCC!$F$2:$F$200)/R13,AVERAGEIFS(LCC!$F$2:$F$200,LCC!$B$2:$B$200,$D13)),IF(AND(U13=1,V13=1),IF(CTRS_Control!$C$19="ZERO",0,IF(CTRS_Control!$C$19="NO_STRESS",100,"")),"")) -> 0 | U13: =IF(COUNTIF(hotel_location_2025!$A$2:$A$110,$B13)>0,1,0) -> 1 | V13: =IF(N13>0,1,0) -> 1 | W13: =IF(R13>0,1,0) -> 0 | X13: =IF(ISNUMBER(K13),1,0) -> 1 | Y13: =IF(AND(AG13=1,ISNUMBER(M13)),1,0) -> 1 | Z13: =IF(Y13=1,IFERROR(IF(CTRS_Control!$C$9="MINMAX",(M13-MIN($M$5:$M$18))/(MAX($M$5:$M$18)-MIN($M$5:$M$18)),M13/MAX($M$5:$M$18)),0),"") -> 0.1500269 | AA13: =IF(Y13=1,IF(AND(R13=0,CTRS_Control!$C$19="MMWQI_ONLY"),1-O13/100,CTRS_Control!$C$15*(1-O13/100)+CTRS_Control!$C$16*(1-S13/100)),"") -> 0.59264706 | AB13: =IF(Y13=1,IF(ISNUMBER(CTRS_Z!$H13),CTRS_Z!$H13,0),"") -> 0 | AC13: =IF(Y13=1,CTRS_Control!$C$12*Z13+CTRS_Control!$C$13*AA13-CTRS_Control!$C$14*AB13,"") -> 0.24755799 | AD13: =IF(Y13=1,(AC13+CTRS_Control!$C$14)/(CTRS_Control!$C$12+CTRS_Control!$C$13+CTRS_Control!$C$14),"") -> 0.58089132 | AE13: =IF(Y13=1,RANK(AC13,$AC$5:$AC$18,0)+COUNTIF($AC$5:AC13,AC13)-1,"") -> 7 | AF13: =IF(U13=0,"No hotel data",IF(V13=0,"No MMWQI stations",IF(AND(W13=0,CTRS_Control!$C$19="EXCLUDE"),"No LCC sites",IF(AND(CTRS_Control!$C$8="TOURISTS",X13=0),"No tourist count",TRIM(IF(AH13=1,"No LCC data → substituted ("&CTRS_Control!$C$19&"). ","")&IF(F13<>G13,"Hotels: reported total "&F13&" ≠ sum of categories "&G13&". ","")&IF(I13<>SUMPRODUCT((hotel_location_2025!$A$2:$A$110=$B13)*(hotel_location_2025!$B$2:$B$110<>"Jumlah/ Total")*hotel_location_2025!$D$2:$D$110),"Rooms: reported total "&I13&" ≠ sum of categories "&SUMPRODUCT((hotel_location_2025!$A$2:$A$110=$B13)*(hotel_location_2025!$B$2:$B$110<>"Jumlah/ Total")*hotel_location_2025!$D$2:$D$110),"")))))) -> No LCC data → substituted (ZERO). | AG13: =U13*V13*IF(OR(W13=1,CTRS_Control!$C$19<>"EXCLUDE"),1,0) -> 1 | AH13: =IF(AND(Y13=1,R13=0),1,0) -> 1
